Workbook

Sheet DASHBOARD
A1: MARÉE — SOCIAL COMMAND CENTER
A2: One place for what's scheduled and what's done across all 5 accounts. Fill the Master Schedule; this dashboard counts itself. Strategy (pillars/voice) lives in the Operating System workbook.
A4: THIS WEEK — your one focus
A5: Type your 1–3 priorities for the week here →
A7: ACCOUNT STATUS (auto-counts from Master Schedule)
A8: Account | B8: Posts total | C8: Captions ✓ | D8: Visuals ✓ | E8: Scheduled | F8: Posted | G8: Next action
A9: Channel South | B9: =COUNTIFS('Master Schedule'!$C:$C,$A9,'Master Schedule'!$F:$F,"<>") | C9: =COUNTIFS('Master Schedule'!$C:$C,$A9,'Master Schedule'!$G:$G,"Y") | D9: =COUNTIFS('Master Schedule'!$C:$C,$A9,'Master Schedule'!$H:$H,"Y") | E9: =COUNTIFS('Master Schedule'!$C:$C,$A9,'Master Schedule'!$J:$J,"Y") | F9: =COUNTIFS('Master Schedule'!$C:$C,$A9,'Master Schedule'!$K:$K,"Y")
A10: Gallery Madison | B10: =COUNTIFS('Master Schedule'!$C:$C,$A10,'Master Schedule'!$F:$F,"<>") | C10: =COUNTIFS('Master Schedule'!$C:$C,$A10,'Master Schedule'!$G:$G,"Y") | D10: =COUNTIFS('Master Schedule'!$C:$C,$A10,'Master Schedule'!$H:$H,"Y") | E10: =COUNTIFS('Master Schedule'!$C:$C,$A10,'Master Schedule'!$J:$J,"Y") | F10: =COUNTIFS('Master Schedule'!$C:$C,$A10,'Master Schedule'!$K:$K,"Y")
A11: Germantown Village | B11: =COUNTIFS('Master Schedule'!$C:$C,$A11,'Master Schedule'!$F:$F,"<>") | C11: =COUNTIFS('Master Schedule'!$C:$C,$A11,'Master Schedule'!$G:$G,"Y") | D11: =COUNTIFS('Master Schedule'!$C:$C,$A11,'Master Schedule'!$H:$H,"Y") | E11: =COUNTIFS('Master Schedule'!$C:$C,$A11,'Master Schedule'!$J:$J,"Y") | F11: =COUNTIFS('Master Schedule'!$C:$C,$A11,'Master Schedule'!$K:$K,"Y")
A12: Bellamare | B12: =COUNTIFS('Master Schedule'!$C:$C,$A12,'Master Schedule'!$F:$F,"<>") | C12: =COUNTIFS('Master Schedule'!$C:$C,$A12,'Master Schedule'!$G:$G,"Y") | D12: =COUNTIFS('Master Schedule'!$C:$C,$A12,'Master Schedule'!$H:$H,"Y") | E12: =COUNTIFS('Master Schedule'!$C:$C,$A12,'Master Schedule'!$J:$J,"Y") | F12: =COUNTIFS('Master Schedule'!$C:$C,$A12,'Master Schedule'!$K:$K,"Y")
A13: Marée Creative | B13: =COUNTIFS('Master Schedule'!$C:$C,$A13,'Master Schedule'!$F:$F,"<>") | C13: =COUNTIFS('Master Schedule'!$C:$C,$A13,'Master Schedule'!$G:$G,"Y") | D13: =COUNTIFS('Master Schedule'!$C:$C,$A13,'Master Schedule'!$H:$H,"Y") | E13: =COUNTIFS('Master Schedule'!$C:$C,$A13,'Master Schedule'!$J:$J,"Y") | F13: =COUNTIFS('Master Schedule'!$C:$C,$A13,'Master Schedule'!$K:$K,"Y")
A14: ALL ACCOUNTS | B14: =SUM(B9:B13) | C14: =SUM(C9:C13) | D14: =SUM(D9:D13) | E14: =SUM(E9:E13) | F14: =SUM(F9:F13)
A16: LEGEND
A17: Master Schedule status columns use Y / N. Fill Caption, Visual, Approved, Scheduled, Posted as you go. Colors flag what's done vs. needs work.

Sheet Master Schedule
A1: MASTER SCHEDULE
A2: Each account is its own colored block. Set status with the Y/N dropdowns — green = done, pink = needs work. Add rows inside an account's block; the Dashboard recounts itself.
A4: CHANNEL SOUTH · @channelsouthms · FB + IG · 3-5x/wk
A5: Date | B5: Day | C5: Account | D5: Platform | E5: Series / Pillar | F5: Headline / Hook | G5: Caption | H5: Visual | I5: Approved | J5: Scheduled | K5: Posted | L5: Publish time | M5: Notes
C6: Channel South
C7: Channel South
C8: Channel South
C9: Channel South
C10: Channel South
C11: Channel South
C12: Channel South
C13: Channel South
C14: Channel South
C15: Channel South
A17: GERMANTOWN VILLAGE · @germantownvillage · FB + IG · Weekly+
A18: Date | B18: Day | C18: Account | D18: Platform | E18: Series / Pillar | F18: Headline / Hook | G18: Caption | H18: Visual | I18: Approved | J18: Scheduled | K18: Posted | L18: Publish time | M18: Notes
C19: Germantown Village
C20: Germantown Village
C21: Germantown Village
C22: Germantown Village
C23: Germantown Village
C24: Germantown Village
C25: Germantown Village
C26: Germantown Village
C27: Germantown Village
C28: Germantown Village
A30: GALLERY MADISON · @thegallerymadison · FB + IG · Weekly
A31: Date | B31: Day | C31: Account | D31: Platform | E31: Series / Pillar | F31: Headline / Hook | G31: Caption | H31: Visual | I31: Approved | J31: Scheduled | K31: Posted | L31: Publish time | M31: Notes
C32: Gallery Madison
C33: Gallery Madison
C34: Gallery Madison
C35: Gallery Madison
C36: Gallery Madison
C37: Gallery Madison
C38: Gallery Madison
C39: Gallery Madison
C40: Gallery Madison
C41: Gallery Madison
A43: BELLAMARE · @bellamaredevelopment · FB · LinkedIn · IG · Weekly
A44: Date | B44: Day | C44: Account | D44: Platform | E44: Series / Pillar | F44: Headline / Hook | G44: Caption | H44: Visual | I44: Approved | J44: Scheduled | K44: Posted | L44: Publish time | M44: Notes
...

Sheet Growth Tracker
A1: GROWTH TRACKER
A2: Baseline once, then log followers/reach/engagement weekly. Δ columns calculate themselves. Bellamare baseline pre-loaded from Jun 23.
A4: BASELINE (set once per account)
A5: Account | B5: Platform | C5: Followers | D5: Mo. Reach | E5: Mo. Interactions | F5: Posts/mo | G5: Top format | H5: Date
A6: Bellamare | B6: Instagram | C6: 192 | D6: 3400 | E6: 27 | F6: 5 | G6: Reels | H6: 6/23/26
A7: Bellamare | B7: Facebook | C7: 400 | D7: 3388 | E7: 26 | F7: 5 | G7: Reels | H7: 6/23/26
A8: Bellamare | B8: LinkedIn | C8: 0 | D8: 0 | E8: 0 | F8: 0 | G8: Not started | H8: 6/23/26
A9: Channel South | B9: FB+IG | C9: 116 | H9: 6/14/26
A10: Gallery Madison | B10: FB+IG | C10: 349 | H10: 6/14/26
A11: Germantown Village | B11: FB+IG | C11: 445 | H11: 6/14/26
A12: Marée Creative | B12: Instagram | C12: 22 | H12: 6/14/26
A15: WEEKLY LOG (fill the blue cells each Friday; Δ vs baseline auto-calcs)
A16: Week of | B16: Account | C16: Followers | D16: Reach | E16: Interactions | F16: Posts | G16: Δ Followers | H16: Notes

Sheet Roadmap
A1: ROADMAP — SETUP & BUILD
A2: The one checklist: get each account set up, built, and scheduled. Tick Y as you finish. Do it top to bottom.
A4: PHASE 1 — SETUP (Meta Business Suite + access)
A5: Account | B5: In Biz Suite | C5: 2FA on | D5: Pw saved | E5: Team access | F5: Login OK | G5: Notes
A6: Channel South
A7: Gallery Madison
A8: Germantown Village
A9: Bellamare
A10: Marée Creative
A12: PHASE 2 — BUILD (per account chat → calendar → schedule)
A13: Account | B13: Comp analysis | C13: Pillars set | D13: Calendar built | E13: Captions done | F13: Scheduled | G13: Notes
A14: Channel South
A15: Gallery Madison
A16: Germantown Village
A17: Bellamare
A18: Marée Creative

Sheet Accounts
A1: ACCOUNTS — REFERENCE
A2: Quick reference per account. Deep strategy (pillars, voice, audit) lives in Evie_Maree_Operating_System.xlsx.
A4: Account | B4: Handle | C4: Platforms | D4: Cadence | E4: Lead pillar | F4: Followers | G4: Note
A5: Channel South | B5: @channelsouthms | C5: FB + IG | D5: 3–5×/wk | E5: Proof & Progress | F5: 116 | G5: Pre-open; countdown + Hotel Holden
A6: Gallery Madison | B6: @thegallerymadison | C6: FB + IG | D6: Weekly | E6: Vision + Place | F6: 349 | G6: Best organic pull; entertainment-retail
A7: Germantown Village | B7: @germantownvillage | C7: FB + IG | D7: Weekly+ | E7: Community & Activation | F7: 445 | G7: Only open account; most material
A8: Bellamare | B8: @bellamaredevelopment | C8: FB · LinkedIn · IG | D8: Weekly | E8: Credibility & Brand | F8: 192 | G8: July campaign loaded in Master Schedule
A9: Marée Creative | B9: @mareecreative_ | C9: IG only | D9: 1–2×/wk | E9: Credibility + Proof | F9: 22 | G9: Cross-tag from the other 4
